Workbook
Name RampList: 'Ranges - Config'!$G$2:$G$5
Name StageList: 'Ranges - Config'!$A$2:$A$6
Name FlexList: 'Ranges - Config'!$F$2:$F$4
Name IndustryList: 'Ranges - Config'!$B$2:$B$6
Name HCList: 'Ranges - Config'!$C$2:$C$3
Name SourceList: 'Ranges - Config'!$H$2:$H$6
Name ConfList: 'Ranges - Config'!$I$2:$I$4
Name PayList: 'Ranges - Config'!$D$2:$D$5
Name EligList: 'Ranges - Config'!$E$2:$E$5

Sheet Read Me
A1: Union — Parental Leave Benchmark Dataset
A3: HOW THIS WORKBOOK WORKS
A4: 1. You only type on the 'Companies' tab: columns A, B, D–S. Everything else computes itself.
A5: 2. Column C (Size Band) and column T (Segment) fill in automatically — don't type in them.
A6: 3. 'Benchmarks' computes n / Min / P25 / Median / P75 / Max per segment, plus the most common (modal) policy settings. All formulas — updates live as rows are added.
A7: 4. 'Tool Export' translates Benchmarks into the generator's vocabulary: min = P25, mid = Median, label = "P25–P75 wks". Paste these into the tool's benchmark table.
A8: 5. 'Config' holds every dropdown list, the size-band cutoffs, and the high-cost metro list. Edit lists there, not in the data tab.
A9: 6. 'Calc' is formula machinery for the modal values on Benchmarks. Ignore it (but don't delete it).
A11: DATA RULES
A12: • No source URL = no row. Rows missing a Source URL turn red; missing Date Verified turns yellow.
A13: • Dropdown columns reject free text — that's what keeps the benchmarks computable.
A14: • Headcount over 200 flags as 'OVER 200 ⚠' in Size Band (outside the dataset's scope).
... A20: Formulas, dropdowns, and the red/yellow highlighting all survive the import.

Sheet Ranges - Config
A1: Funding Stage | B1: Industry | C1: High-Cost | D1: Pay Structure | E1: Eligibility | F1: Flexibility | G1: Ramp-Up | H1: Source Type | I1: Confidence | J1: High-Cost Metros
A2: Pre-seed/Seed | B2: Tech | C2: Y | D2: 100% top-up | E2: Day 1 | F2: Single block | G2: None | H2: Company handbook | I2: High | J2: SF Bay Area
A3: Series A | B3: Enterprise SaaS | C3: N | D3: Partial top-up | E3: 90 days | F3: 2 chunks | G3: <=1 wk | H3: Careers/benefits page | I3: Medium | J3: NYC
A4: Series B+ | B4: Fintech | D4: STD only | E4: 6 months | F4: Flexible chunks / 12 mo | G4: 1-2 wks | H4: Press coverage | I4: Low | J4: Seattle
A5: Bootstrapped | B5: Biotech | D5: Unpaid beyond legal | E5: 12 months | G5: 2-4 wks | H5: Benchmark report
A6: Unknown | B6: Other | H6: Job posting
A9: Size band cutoffs (edit here):
A10: Band 1 max | B10: 25
A11: Band 2 max | B11: 75
A12: Band 3 max | B12: 200

Sheet Companies
A1: Company Name | B1: Headcount | C1: Size Band | D1: Funding Stage | E1: Industry | F1: HQ Metro/State | G1: High-Cost Market | H1: Birthing Parent Leave (wks) | I1: Non-Birthing Parent Leave (wks) | J1: Pay Structure | K1: Pay % (if partial) | L1: Eligibility | M1: Flexibility | N1: Ramp-Up Program | O1: Source Type | P1: Source of Truth URL | Q1: Date Verified | R1: Confidence | S1: Notes | T1: Segment (auto)
A2: EXAMPLE — Acme Robotics (replace me) | B2: 42 | C2: =IF($B2="","",IF($B2<='Ranges - Config'!$B$10,"1-25",IF($B2<='Ranges - Config'!$B$11,"26-75",IF($B2<='Ranges - Config'!$B$12,"76-200","OVER 200 !")))) -> 26-75 | D2: Series A | E2: Tech | F2: New York, NY | G2: Y | H2: 14 | I2: 8 | J2: 100% top-up | L2: 90 days | M2: Flexible chunks / 12 mo | N2: 1-2 wks | O2: Careers/benefits page | P2: https://example.com/benefits | Q2: 46215 | R2: High | S2: Worked example showing expected format — delete before analysis | T2: =IF(OR($D2="",$G2=""),"",IF(OR($D2="Bootstrapped",$D2="Unknown"),"Not benchmarked",IF($D2="Pre-seed/Seed","Seed",$D2)&" | "&IF($G2="Y","High-cost","Standard"))) -> Series A | High-cost
A3: PostHog | B3: 195 | D3: Series B+ | E3: Enterprise SaaS | F3: San Francisco, CA | G3: Y | H3: 24 | I3: 4 | J3: 100% top-up | L3: 12 months | M3: Single block | O3: Company handbook | P3: https://posthog.com/handbook/people/time-off | Q3: 46215 | R3: High | S3: Headcount estimate 185-202, near/at 200 cap — verify before relying on this row
A4: Homebot | B4: 65 | D4: Pre-seed/Seed | E4: Fintech | F4: Denver, CO | G4: N | H4: 12 | I4: 12 | J4: 100% top-up | O4: Careers/benefits page | P4: https://homebot.ai/careers | Q4: 46215 | R4: High | S4: Headcount is a rough estimate (50-75 range) | T4: =IF(OR($D4="",$G4=""),"",IF(OR($D4="Bootstrapped",$D4="Unknown"),"Not benchmarked",IF($D4="Pre-seed/Seed","Seed",$D4)&" | "&IF($G4="Y","High-cost","Standard"))) -> Seed | Standard
A5: Formation Bio | B5: 170 | D5: Series B+ | E5: Biotech | F5: New York, NY | G5: Y | H5: 16 | I5: 12 | J5: 100% top-up | O5: Careers/benefits page | P5: https://www.formation.bio/careers | Q5: 46215 | R5: High | S5: Headcount estimate 150-188, growing toward cap — verify | T5: =IF(OR($D5="",$G5=""),"",IF(OR($D5="Bootstrapped",$D5="Unknown"),"Not benchmarked",IF($D5="Pre-seed/Seed","Seed",$D5)&" | "&IF($G5="Y","High-cost","Standard"))) -> Series B+ | High-cost
A6: January | B6: 58 | D6: Series B+ | E6: Fintech | F6: New York, NY | G6: Y | H6: 12 | I6: 12 | J6: 100% top-up | O6: Press coverage | P6: https://builtin.com/articles/companies-best-maternal-parental-leave | Q6: 46217 | R6: High | S6: Leave must be used within first year of birth/adoption (usage window, not tenure gate) | T6: =IF(OR($D6="",$G6=""),"",IF(OR($D6="Bootstrapped",$D6="Unknown"),"Not benchmarked",IF($D6="Pre-seed/Seed","Seed",$D6)&" | "&IF($G6="Y","High-cost","Standard"))) -> Series B+ | High-cost
A7: ePayPolicy | B7: 155 | D7: Series B+ | E7: Fintech | F7: Austin, TX | G7: N | H7: 20 | I7: 14 | J7: 100% top-up | M7: Flexible chunks / 12 mo | O7: Press coverage | P7: https://builtin.com/articles/companies-best-maternal-parental-leave | Q7: 46217 | R7: High | S7: PE/growth-backed (Serent, LLR) not classic VC — confirm this fits "venture-backed." Birthing = 14wk paid + 6wk STD | T7: =IF(OR($D7="",$G7=""),"",IF(OR($D7="Bootstrapped",$D7="Unknown"),"Not benchmarked",IF($D7="Pre-seed/Seed","Seed",$D7)&" | "&IF($G7="Y","High-cost","Standard"))) -> Series B+ | Standard
A8: Soofa | B8: 30 | D8: Pre-seed/Seed | E8: Other | F8: Cambridge, MA | G8: N | H8: 8 | J8: 100% top-up | N8: 2-4 wks | O8: Press coverage | P8: https://theorg.com/iterate/what-can-parental-leave-look-like-at-an-early-stage-startup | Q8: 46217 | R8: High | S8: Conflicts with Built In Boston (12wk/2wk) — unresolved, treat as unconfirmed | T8: =IF(OR($D8="",$G8=""),"",IF(OR($D8="Bootstrapped",$D8="Unknown"),"Not benchmarked",IF($D8="Pre-seed/Seed","Seed",$D8)&" | "&IF($G8="Y","High-cost","Standard"))) -> Seed | Standard
A9: HMBradley | B9: 40 | D9: Series B+ | E9: Fintech | F9: Los Angeles, CA | G9: N | H9: 12 | I9: 12 | J9: 100% top-up | O9: Job posting | P9: https://www.linkedin.com/company/hmbradley | Q9: 46217 | R9: High | S9: Company shut consumer product and pivoted 2023; verify policy still applies post-pivot | T9: =IF(OR($D9="",$G9=""),"",IF(OR($D9="Bootstrapped",$D9="Unknown"),"Not benchmarked",IF($D9="Pre-seed/Seed","Seed",$D9)&" | "&IF($G9="Y","High-cost","Standard"))) -> Series B+ | Standard
A10: Fleetio | B10: 164 | D10: Series B+ | E10: Tech | F10: Birmingham, AL | G10: N | H10: 16 | I10: 4 | J10: 100% top-up | O10: Careers/benefits page | P10: https://www.fleetio.com/careers | Q10: 46217 | R10: High | S10: Headcount confirmed via Built In (164). Funding stage estimated Series B+ (multiple VC rounds); confirm exact stage before treating as High on that field.
A11: [TEST] Nova Health | B11: 18 | D11: Series A | E11: Fintech | F11: Austin, TX | G11: N | H11: 11 | I11: 6 | J11: Partial top-up | K11: 80 | L11: Day 1 | M11: Flexible chunks / 12 mo | N11: <=1 wk | O11: TEST DATA | P11: N/A - synthetic test row | Q11: 46219 | R11: Test | S11: SYNTHETIC TEST ROW — generated for pipeline/formula testing only. Not a real company. Do not treat as verified benchmark data. | T11: =IF(OR($D11="",$G11=""),"",IF(OR($D11="Bootstrapped",$D11="Unknown"),"Not benchmarked",IF($D11="Pre-seed/Seed","Seed",$D11)&" | "&IF($G11="Y","High-cost","Standard"))) -> Series A | Standard
A12: [TEST] Loom Labs | B12: 35 | D12: Pre-seed/Seed | E12: Other | F12: San Francisco, CA | G12: Y | H12: 14 | I12: 3 | J12: Partial top-up | K12: 80 | L12: 12 months | M12: Single block | N12: <=1 wk | O12: TEST DATA | P12: N/A - synthetic test row | Q12: 46219 | R12: Test | S12: SYNTHETIC TEST ROW — generated for pipeline/formula testing only. Not a real company. Do not treat as verified benchmark data. | T12: =IF(OR($D12="",$G12=""),"",IF(OR($D12="Bootstrapped",$D12="Unknown"),"Not benchmarked",IF($D12="Pre-seed/Seed","Seed",$D12)&" | "&IF($G12="Y","High-cost","Standard"))) -> Seed | High-cost
A13: [TEST] Clear Group | B13: 80 | D13: Series B+ | E13: Biotech | F13: Chicago, IL | G13: N | H13: 14 | I13: 6 | J13: 100% top-up | L13: 6 months | M13: Single block | N13: None | O13: TEST DATA | P13: N/A - synthetic test row | Q13: 46219 | R13: Test | S13: SYNTHETIC TEST ROW — generated for pipeline/formula testing only. Not a real company. Do not treat as verified benchmark data. | T13: =IF(OR($D13="",$G13=""),"",IF(OR($D13="Bootstrapped",$D13="Unknown"),"Not benchmarked",IF($D13="Pre-seed/Seed","Seed",$D13)&" | "&IF($G13="Y","High-cost","Standard"))) -> Series B+ | Standard
A14: [TEST] Fable Field | B14: 194 | D14: Series B+ | E14: Fintech | F14: San Francisco, CA | G14: Y | H14: 21 | I14: 11 | J14: 100% top-up | L14: 12 months | M14: Single block | N14: <=1 wk | O14: TEST DATA | P14: N/A - synthetic test row | Q14: 46219 | R14: Test | S14: SYNTHETIC TEST ROW — generated for pipeline/formula testing only. Not a real company. Do not treat as verified benchmark data. | T14: =IF(OR($D14="",$G14=""),"",IF(OR($D14="Bootstrapped",$D14="Unknown"),"Not benchmarked",IF($D14="Pre-seed/Seed","Seed",$D14)&" | "&IF($G14="Y","High-cost","Standard"))) -> Series B+ | High-cost
A15: [TEST] Grove Cloud | B15: 132 | D15: Series B+ | E15: Other | F15: Austin, TX | G15: N | H15: 21 | I15: 5 | J15: 100% top-up | L15: 90 days | M15: 2 chunks | N15: 2-4 wks | O15: TEST DATA | P15: N/A - synthetic test row | Q15: 46219 | R15: Test | S15: SYNTHETIC TEST ROW — generated for pipeline/formula testing only. Not a real company. Do not treat as verified benchmark data. | T15: =IF(OR($D15="",$G15=""),"",IF(OR($D15="Bootstrapped",$D15="Unknown"),"Not benchmarked",IF($D15="Pre-seed/Seed","Seed",$D15)&" | "&IF($G15="Y","High-cost","Standard"))) -> Series B+ | Standard
A16: [TEST] Onyx Health | B16: 137 | D16: Series B+ | E16: Fintech | F16: Minneapolis, MN | G16: N | H16: 20 | I16: 9 | J16: 100% top-up | L16: 6 months | M16: Single block | N16: 1-2 wks | O16: TEST DATA | P16: N/A - synthetic test row | Q16: 46219 | R16: Test | S16: SYNTHETIC TEST ROW — generated for pipeline/formula testing only. Not a real company. Do not treat as verified benchmark data. | T16: =IF(OR($D16="",$G16=""),"",IF(OR($D16="Bootstrapped",$D16="Unknown"),"Not benchmarked",IF($D16="Pre-seed/Seed","Seed",$D16)&" | "&IF($G16="Y","High-cost","Standard"))) -> Series B+ | Standard
A17: [TEST] Drift Works | B17: 36 | D17: Series A | E17: Other | F17: Austin, TX | G17: N | H17: 10 | I17: 7 | J17: 100% top-up | L17: 90 days | M17: Flexible chunks / 12 mo | N17: None | O17: TEST DATA | P17: N/A - synthetic test row | Q17: 46219 | R17: Test | S17: SYNTHETIC TEST ROW — generated for pipeline/formula testing only. Not a real company. Do not treat as verified benchmark data. | T17: =IF(OR($D17="",$G17=""),"",IF(OR($D17="Bootstrapped",$D17="Unknown"),"Not benchmarked",IF($D17="Pre-seed/Seed","Seed",$D17)&" | "&IF($G17="Y","High-cost","Standard"))) -> Series A | Standard
A18: [TEST] Harbor Ventures | B18: 5 | D18: Pre-seed/Seed | E18: Fintech | F18: Atlanta, GA | G18: N | H18: 10 | I18: 2 | J18: 100% top-up | L18: 6 months | M18: Single block | N18: 1-2 wks | O18: TEST DATA | P18: N/A - synthetic test row | Q18: 46219 | R18: Test | S18: SYNTHETIC TEST ROW — generated for pipeline/formula testing only. Not a real company. Do not treat as verified benchmark data. | T18: =IF(OR($D18="",$G18=""),"",IF(OR($D18="Bootstrapped",$D18="Unknown"),"Not benchmarked",IF($D18="Pre-seed/Seed","Seed",$D18)&" | "&IF($G18="Y","High-cost","Standard"))) -> Seed | Standard
A19: [TEST] North AI | B19: 11 | D19: Pre-seed/Seed | E19: Enterprise SaaS | F19: Raleigh, NC | G19: N | H19: 14 | I19: 4 | J19: Partial top-up | K19: 75 | L19: 12 months | M19: 2 chunks | N19: None | O19: TEST DATA | P19: N/A - synthetic test row | Q19: 46219 | R19: Test | S19: SYNTHETIC TEST ROW — generated for pipeline/formula testing only. Not a real company. Do not treat as verified benchmark data. | T19: =IF(OR($D19="",$G19=""),"",IF(OR($D19="Bootstrapped",$D19="Unknown"),"Not benchmarked",IF($D19="Pre-seed/Seed","Seed",$D19)&" | "&IF($G19="Y","High-cost","Standard"))) -> Seed | Standard
A20: [TEST] Pivot AI | B20: 21 | D20: Series A | E20: Tech | F20: Seattle, WA | G20: Y | H20: 18 | I20: 6 | J20: Partial top-up | K20: 75 | L20: Day 1 | M20: 2 chunks | N20: None | O20: TEST DATA | P20: N/A - synthetic test row | Q20: 46219 | R20: Test | S20: SYNTHETIC TEST ROW — generated for pipeline/formula testing only. Not a real company. Do not treat as verified benchmark data. | T20: =IF(OR($D20="",$G20=""),"",IF(OR($D20="Bootstrapped",$D20="Unknown"),"Not benchmarked",IF($D20="Pre-seed/Seed","Seed",$D20)&" | "&IF($G20="Y","High-cost","Standard"))) -> Series A | High-cost
A21: [TEST] Blue Ventures | B21: 38 | D21: Pre-seed/Seed | E21: Tech | F21: New York, NY | G21: Y | H21: 14 | I21: 8 | J21: 100% top-up | L21: 6 months | M21: Single block | N21: None | O21: TEST DATA | P21: N/A - synthetic test row | Q21: 46219 | R21: Test | S21: SYNTHETIC TEST ROW — generated for pipeline/formula testing only. Not a real company. Do not treat as verified benchmark data. | T21: =IF(OR($D21="",$G21=""),"",IF(OR($D21="Bootstrapped",$D21="Unknown"),"Not benchmarked",IF($D21="Pre-seed/Seed","Seed",$D21)&" | "&IF($G21="Y","High-cost","Standard"))) -> Seed | High-cost
A22: [TEST] Cobalt Analytics | B22: 19 | D22: Pre-seed/Seed | E22: Other | F22: Seattle, WA | G22: Y | H22: 14 | I22: 2 | J22: STD only | L22: 6 months | M22: Flexible chunks / 12 mo | N22: <=1 wk | O22: TEST DATA | P22: N/A - synthetic test row | Q22: 46219 | R22: Test | S22: SYNTHETIC TEST ROW — generated for pipeline/formula testing only. Not a real company. Do not treat as verified benchmark data. | T22: =IF(OR($D22="",$G22=""),"",IF(OR($D22="Bootstrapped",$D22="Unknown"),"Not benchmarked",IF($D22="Pre-seed/Seed","Seed",$D22)&" | "&IF($G22="Y","High-cost","Standard"))) -> Seed | High-cost
A23: [TEST] Kindle Studio | B23: 35 | D23: Series A | E23: Other | F23: Raleigh, NC | G23: N | H23: 8 | I23: 8 | J23: 100% top-up | L23: Day 1 | M23: Single block | N23: 2-4 wks | O23: TEST DATA | P23: N/A - synthetic test row | Q23: 46219 | R23: Test | S23: SYNTHETIC TEST ROW — generated for pipeline/formula testing only. Not a real company. Do not treat as verified benchmark data. | T23: =IF(OR($D23="",$G23=""),"",IF(OR($D23="Bootstrapped",$D23="Unknown"),"Not benchmarked",IF($D23="Pre-seed/Seed","Seed",$D23)&" | "&IF($G23="Y","High-cost","Standard"))) -> Series A | Standard
A24: [TEST] North Solutions | B24: 18 | D24: Pre-seed/Seed | E24: Other | F24: New York, NY | G24: Y | H24: 7 | I24: 7 | J24: 100% top-up | L24: Day 1 | M24: Flexible chunks / 12 mo | N24: 1-2 wks | O24: TEST DATA | P24: N/A - synthetic test row | Q24: 46219 | R24: Test | S24: SYNTHETIC TEST ROW — generated for pipeline/formula testing only. Not a real company. Do not treat as verified benchmark data. | T24: =IF(OR($D24="",$G24=""),"",IF(OR($D24="Bootstrapped",$D24="Unknown"),"Not benchmarked",IF($D24="Pre-seed/Seed","Seed",$D24)&" | "&IF($G24="Y","High-cost","Standard"))) -> Seed | High-cost
A25: [TEST] Onyx Bio | B25: 82 | D25: Series B+ | E25: Fintech | F25: Raleigh, NC | G25: N | H25: 23 | I25: 13 | J25: 100% top-up | L25: 90 days | M25: Flexible chunks / 12 mo | N25: 1-2 wks | O25: TEST DATA | P25: N/A - synthetic test row | Q25: 46219 | R25: Test | S25: SYNTHETIC TEST ROW — generated for pipeline/formula testing only. Not a real company. Do not treat as verified benchmark data. | T25: =IF(OR($D25="",$G25=""),"",IF(OR($D25="Bootstrapped",$D25="Unknown"),"Not benchmarked",IF($D25="Pre-seed/Seed","Seed",$D25)&" | "&IF($G25="Y","High-cost","Standard"))) -> Series B+ | Standard
A26: [TEST] Nova Logic | B26: 142 | D26: Series B+ | E26: Fintech | F26: Minneapolis, MN | G26: N | H26: 24 | I26: 12 | J26: 100% top-up | L26: 90 days | M26: Single block | N26: None | O26: TEST DATA | P26: N/A - synthetic test row | Q26: 46219 | R26: Test | S26: SYNTHETIC TEST ROW — generated for pipeline/formula testing only. Not a real company. Do not treat as verified benchmark data. | T26: =IF(OR($D26="",$G26=""),"",IF(OR($D26="Bootstrapped",$D26="Unknown"),"Not benchmarked",IF($D26="Pre-seed/Seed","Seed",$D26)&" | "&IF($G26="Y","High-cost","Standard"))) -> Series B+ | Standard
A27: [TEST] Summit AI | B27: 90 | D27: Series A | E27: Enterprise SaaS | F27: San Francisco, CA | G27: Y | H27: 9 | I27: 9 | J27: Partial top-up | K27: 60 | L27: Day 1 | M27: Single block | N27: 2-4 wks | O27: TEST DATA | P27: N/A - synthetic test row | Q27: 46219 | R27: Test | S27: SYNTHETIC TEST ROW — generated for pipeline/formula testing only. Not a real company. Do not treat as verified benchmark data. | T27: =IF(OR($D27="",$G27=""),"",IF(OR($D27="Bootstrapped",$D27="Unknown"),"Not benchmarked",IF($D27="Pre-seed/Seed","Seed",$D27)&" | "&IF($G27="Y","High-cost","Standard"))) -> Series A | High-cost
A28: [TEST] Marsh Networks | B28: 34 | D28: Pre-seed/Seed | E28: Enterprise SaaS | F28: Raleigh, NC | G28: N | H28: 8 | I28: 7 | J28: STD only | L28: 12 months | M28: Single block | N28: 1-2 wks | O28: TEST DATA | P28: N/A - synthetic test row | Q28: 46219 | R28: Test | S28: SYNTHETIC TEST ROW — generated for pipeline/formula testing only. Not a real company. Do not treat as verified benchmark data. | T28: =IF(OR($D28="",$G28=""),"",IF(OR($D28="Bootstrapped",$D28="Unknown"),"Not benchmarked",IF($D28="Pre-seed/Seed","Seed",$D28)&" | "&IF($G28="Y","High-cost","Standard"))) -> Seed | Standard
A29: [TEST] Maple Robotics | B29: 9 | D29: Pre-seed/Seed | E29: Biotech | F29: Chicago, IL | G29: N | H29: 12 | I29: 5 | J29: 100% top-up | L29: Day 1 | M29: Flexible chunks / 12 mo | N29: 1-2 wks | O29: TEST DATA | P29: N/A - synthetic test row | Q29: 46219 | R29: Test | S29: SYNTHETIC TEST ROW — generated for pipeline/formula testing only. Not a real company. Do not treat as verified benchmark data. | T29: =IF(OR($D29="",$G29=""),"",IF(OR($D29="Bootstrapped",$D29="Unknown"),"Not benchmarked",IF($D29="Pre-seed/Seed","Seed",$D29)&" | "&IF($G29="Y","High-cost","Standard"))) -> Seed | Standard
A30: [TEST] Pivot Cloud | B30: 24 | D30: Pre-seed/Seed | E30: Tech | F30: Austin, TX | G30: N | H30: 9 | I30: 3 | J30: 100% top-up | L30: 90 days | M30: 2 chunks | N30: None | O30: TEST DATA | P30: N/A - synthetic test row | Q30: 46219 | R30: Test | S30: SYNTHETIC TEST ROW — generated for pipeline/formula testing only. Not a real company. Do not treat as verified benchmark data. | T30: =IF(OR($D30="",$G30=""),"",IF(OR($D30="Bootstrapped",$D30="Unknown"),"Not benchmarked",IF($D30="Pre-seed/Seed","Seed",$D30)&" | "&IF($G30="Y","High-cost","Standard"))) -> Seed | Standard
A31: [TEST] Blue Networks | B31: 59 | D31: Series B+ | E31: Biotech | F31: Raleigh, NC | G31: N | H31: 11 | I31: 4 | J31: Partial top-up | K31: 80 | L31: Day 1 | M31: Single block | N31: 2-4 wks | O31: TEST DATA | P31: N/A - synthetic test row | Q31: 46219 | R31: Test | S31: SYNTHETIC TEST ROW — generated for pipeline/formula testing only. Not a real company. Do not treat as verified benchmark data. | T31: =IF(OR($D31="",$G31=""),"",IF(OR($D31="Bootstrapped",$D31="Unknown"),"Not benchmarked",IF($D31="Pre-seed/Seed","Seed",$D31)&" | "&IF($G31="Y","High-cost","Standard"))) -> Series B+ | Standard
A32: [TEST] Marsh Ventures | B32: 42 | D32: Series A | E32: Biotech | F32: San Francisco, CA | G32: Y | H32: 10 | I32: 7 | J32: 100% top-up | L32: 12 months | M32: 2 chunks | N32: 2-4 wks | O32: TEST DATA | P32: N/A - synthetic test row | Q32: 46219 | R32: Test | S32: SYNTHETIC TEST ROW — generated for pipeline/formula testing only. Not a real company. Do not treat as verified benchmark data. | T32: =IF(OR($D32="",$G32=""),"",IF(OR($D32="Bootstrapped",$D32="Unknown"),"Not benchmarked",IF($D32="Pre-seed/Seed","Seed",$D32)&" | "&IF($G32="Y","High-cost","Standard"))) -> Series A | High-cost
A33: [TEST] Bright Technologies | B33: 38 | D33: Pre-seed/Seed | E33: Biotech | F33: Seattle, WA | G33: Y | H33: 9 | I33: 4 | J33: 100% top-up | L33: Day 1 | M33: Flexible chunks / 12 mo | N33: 1-2 wks | O33: TEST DATA | P33: N/A - synthetic test row | Q33: 46219 | R33: Test | S33: SYNTHETIC TEST ROW — generated for pipeline/formula testing only. Not a real company. Do not treat as verified benchmark data. | T33: =IF(OR($D33="",$G33=""),"",IF(OR($D33="Bootstrapped",$D33="Unknown"),"Not benchmarked",IF($D33="Pre-seed/Seed","Seed",$D33)&" | "&IF($G33="Y","High-cost","Standard"))) -> Seed | High-cost
A34: [TEST] Summit Cloud | B34: 40 | D34: Pre-seed/Seed | E34: Biotech | F34: Raleigh, NC | G34: N | H34: 14 | I34: 3 | J34: 100% top-up | L34: Day 1 | M34: Single block | N34: None | O34: TEST DATA | P34: N/A - synthetic test row | Q34: 46219 | R34: Test | S34: SYNTHETIC TEST ROW — generated for pipeline/formula testing only. Not a real company. Do not treat as verified benchmark data. | T34: =IF(OR($D34="",$G34=""),"",IF(OR($D34="Bootstrapped",$D34="Unknown"),"Not benchmarked",IF($D34="Pre-seed/Seed","Seed",$D34)&" | "&IF($G34="Y","High-cost","Standard"))) -> Seed | Standard
A35: [TEST] Onyx Technologies | B35: 87 | D35: Series A | E35: Enterprise SaaS | F35: Columbus, OH | G35: N | H35: 17 | I35: 4 | J35: Partial top-up | K35: 75 | L35: 6 months | M35: 2 chunks | N35: None | O35: TEST DATA | P35: N/A - synthetic test row | Q35: 46219 | R35: Test | S35: SYNTHETIC TEST ROW — generated for pipeline/formula testing only. Not a real company. Do not treat as verified benchmark data. | T35: =IF(OR($D35="",$G35=""),"",IF(OR($D35="Bootstrapped",$D35="Unknown"),"Not benchmarked",IF($D35="Pre-seed/Seed","Seed",$D35)&" | "&IF($G35="Y","High-cost","Standard"))) -> Series A | Standard
A36: [TEST] Quartz Robotics | B36: 28 | D36: Pre-seed/Seed | E36: Enterprise SaaS | F36: Denver, CO | G36: N | H36: 13 | I36: 4 | J36: STD only | L36: Day 1 | M36: Single block | N36: <=1 wk | O36: TEST DATA | P36: N/A - synthetic test row | Q36: 46219 | R36: Test | S36: SYNTHETIC TEST ROW — generated for pipeline/formula testing only. Not a real company. Do not treat as verified benchmark data. | T36: =IF(OR($D36="",$G36=""),"",IF(OR($D36="Bootstrapped",$D36="Unknown"),"Not benchmarked",IF($D36="Pre-seed/Seed","Seed",$D36)&" | "&IF($G36="Y","High-cost","Standard"))) -> Seed | Standard
A37: [TEST] Pivot Data | B37: 16 | D37: Pre-seed/Seed | E37: Other | F37: Denver, CO | G37: N | H37: 8 | I37: 4 | J37: STD only | L37: 90 days | M37: 2 chunks | N37: None | O37: TEST DATA | P37: N/A - synthetic test row | Q37: 46219 | R37: Test | S37: SYNTHETIC TEST ROW — generated for pipeline/formula testing only. Not a real company. Do not treat as verified benchmark data. | T37: =IF(OR($D37="",$G37=""),"",IF(OR($D37="Bootstrapped",$D37="Unknown"),"Not benchmarked",IF($D37="Pre-seed/Seed","Seed",$D37)&" | "&IF($G37="Y","High-cost","Standard"))) -> Seed | Standard
A38: [TEST] Kindle Robotics | B38: 196 | D38: Series B+ | E38: Other | F38: San Francisco, CA | G38: Y | H38: 20 | I38: 12 | J38: 100% top-up | L38: Day 1 | M38: Single block | N38: None | O38: TEST DATA | P38: N/A - synthetic test row | Q38: 46219 | R38: Test | S38: SYNTHETIC TEST ROW — generated for pipeline/formula testing only. Not a real company. Do not treat as verified benchmark data. | T38: =IF(OR($D38="",$G38=""),"",IF(OR($D38="Bootstrapped",$D38="Unknown"),"Not benchmarked",IF($D38="Pre-seed/Seed","Seed",$D38)&" | "&IF($G38="Y","High-cost","Standard"))) -> Series B+ | High-cost
A39: [TEST] Kindle Works | B39: 79 | D39: Series B+ | E39: Fintech | F39: Denver, CO | G39: N | H39: 19 | I39: 7 | J39: Partial top-up | K39: 60 | L39: 6 months | M39: Flexible chunks / 12 mo | N39: <=1 wk | O39: TEST DATA | P39: N/A - synthetic test row | Q39: 46219 | R39: Test | S39: SYNTHETIC TEST ROW — generated for pipeline/formula testing only. Not a real company. Do not treat as verified benchmark data. | T39: =IF(OR($D39="",$G39=""),"",IF(OR($D39="Bootstrapped",$D39="Unknown"),"Not benchmarked",IF($D39="Pre-seed/Seed","Seed",$D39)&" | "&IF($G39="Y","High-cost","Standard"))) -> Series B+ | Standard
A40: [TEST] Onyx Networks | B40: 30 | D40: Pre-seed/Seed | E40: Fintech | F40: San Francisco, CA | G40: Y | H40: 6 | I40: 4 | J40: Partial top-up | K40: 70 | L40: 90 days | M40: Flexible chunks / 12 mo | N40: <=1 wk | O40: TEST DATA | P40: N/A - synthetic test row | Q40: 46219 | R40: Test | S40: SYNTHETIC TEST ROW — generated for pipeline/formula testing only. Not a real company. Do not treat as verified benchmark data. | T40: =IF(OR($D40="",$G40=""),"",IF(OR($D40="Bootstrapped",$D40="Unknown"),"Not benchmarked",IF($D40="Pre-seed/Seed","Seed",$D40)&" | "&IF($G40="Y","High-cost","Standard"))) -> Seed | High-cost
...

Sheet Benchmarks
A1: Segment | B1: Funding Stage | C1: Cost of Market | D1: # of Companies in Sample | E1: Sample Size Warning (Less than 30) | F1: Birthing Parent Minimum (weeks) | G1: Birthing Parent Bottom 25% (weeks) | H1: Birthing Parent Median (weeks) | I1: Birthing Parent top 75% (weeks) | J1: Birthing Parent Max (weeks) | K1: Non-Birthing Parent Minimum (weeks) | L1: Non-Birthing Parent Bottom 25% (weeks) | M1: Non-Birthing Parent Median (weeks) | N1: Non-Birthing Parent top 75% (weeks) | O1: Non-Birthing Parent Max (weeks) | P1: Pay Structure (typical) | Q1: Eligibility (typical) | R1: Flexibility (typical) | S1: Ramp-Up (typical)
A2: Seed | Standard | B2: Seed | C2: Standard | D2: =COUNTIFS(Companies!$T$2:$T$301,$A2,Companies!$H$2:$H$301,">=0") -> 52 | E2: =IF($D2=0,"NO DATA",IF($D2<30,"LOW SAMPLE (n<30)","")) | F2: {=IFERROR(IF($D2=0,"",MIN(IF((Companies!$T$2:$T$301=$A2)*ISNUMBER(Companies!$H$2:$H$301),Companies!$H$2:$H$301))),"")} -> 6 | G2: {=IFERROR(IF($D2=0,"",QUARTILE(IF((Companies!$T$2:$T$301=$A2)*ISNUMBER(Companies!$H$2:$H$301),Companies!$H$2:$H$301),1)),"")} -> 9 | H2: {=IFERROR(IF($D2=0,"",MEDIAN(IF((Companies!$T$2:$T$301=$A2)*ISNUMBER(Companies!$H$2:$H$301),Companies!$H$2:$H$301))),"")} -> 11 | I2: {=IFERROR(IF($D2=0,"",QUARTILE(IF((Companies!$T$2:$T$301=$A2)*ISNUMBER(Companies!$H$2:$H$301),Companies!$H$2:$H$301),3)),"")} -> 12.25 | J2: {=IFERROR(IF($D2=0,"",MAX(IF((Companies!$T$2:$T$301=$A2)*ISNUMBER(Companies!$H$2:$H$301),Companies!$H$2:$H$301))),"")} -> 14 | K2: {=IFERROR(IF($D2=0,"",MIN(IF((Companies!$T$2:$T$301=$A2)*ISNUMBER(Companies!$I$2:$I$301),Companies!$I$2:$I$301))),"")} -> 2 | L2: {=IFERROR(IF($D2=0,"",QUARTILE(IF((Companies!$T$2:$T$301=$A2)*ISNUMBER(Companies!$I$2:$I$301),Companies!$I$2:$I$301),1)),"")} -> 3 | M2: {=IFERROR(IF($D2=0,"",MEDIAN(IF((Companies!$T$2:$T$301=$A2)*ISNUMBER(Companies!$I$2:$I$301),Companies!$I$2:$I$301))),"")} -> 5 | N2: {=IFERROR(IF($D2=0,"",QUARTILE(IF((Companies!$T$2:$T$301=$A2)*ISNUMBER(Companies!$I$2:$I$301),Companies!$I$2:$I$301),3)),"")} -> 7 | O2: {=IFERROR(IF($D2=0,"",MAX(IF((Companies!$T$2:$T$301=$A2)*ISNUMBER(Companies!$I$2:$I$301),Companies!$I$2:$I$301))),"")} -> 12 | P2: {=IF(MAX(Calc!$B4:$E4)=0,"",INDEX(Calc!$B$3:$E$3,MATCH(MAX(Calc!$B4:$E4),Calc!$B4:$E4,0)))} -> 100% top-up | Q2: {=IF(MAX(Calc!$G4:$J4)=0,"",INDEX(Calc!$G$3:$J$3,MATCH(MAX(Calc!$G4:$J4),Calc!$G4:$J4,0)))} -> 12 months | R2: {=IF(MAX(Calc!$L4:$N4)=0,"",INDEX(Calc!$L$3:$N$3,MATCH(MAX(Calc!$L4:$N4),Calc!$L4:$N4,0)))} -> Single block | S2: {=IF(MAX(Calc!$P4:$S4)=0,"",INDEX(Calc!$P$3:$S$3,MATCH(MAX(Calc!$P4:$S4),Calc!$P4:$S4,0)))} -> None
A3: Seed | High-cost | B3: Seed | C3: High-cost | D3: =COUNTIFS(Companies!$T$2:$T$301,$A3,Companies!$H$2:$H$301,">=0") -> 21 | E3: =IF($D3=0,"NO DATA",IF($D3<30,"LOW SAMPLE (n<30)","")) -> LOW SAMPLE (n<30) | F3: {=IFERROR(IF($D3=0,"",MIN(IF((Companies!$T$2:$T$301=$A3)*ISNUMBER(Companies!$H$2:$H$301),Companies!$H$2:$H$301))),"")} -> 6 | G3: {=IFERROR(IF($D3=0,"",QUARTILE(IF((Companies!$T$2:$T$301=$A3)*ISNUMBER(Companies!$H$2:$H$301),Companies!$H$2:$H$301),1)),"")} -> 8 | H3: {=IFERROR(IF($D3=0,"",MEDIAN(IF((Companies!$T$2:$T$301=$A3)*ISNUMBER(Companies!$H$2:$H$301),Companies!$H$2:$H$301))),"")} -> 10 | I3: {=IFERROR(IF($D3=0,"",QUARTILE(IF((Companies!$T$2:$T$301=$A3)*ISNUMBER(Companies!$H$2:$H$301),Companies!$H$2:$H$301),3)),"")} -> 13 | J3: {=IFERROR(IF($D3=0,"",MAX(IF((Companies!$T$2:$T$301=$A3)*ISNUMBER(Companies!$H$2:$H$301),Companies!$H$2:$H$301))),"")} -> 14 | K3: {=IFERROR(IF($D3=0,"",MIN(IF((Companies!$T$2:$T$301=$A3)*ISNUMBER(Companies!$I$2:$I$301),Companies!$I$2:$I$301))),"")} -> 2 | L3: {=IFERROR(IF($D3=0,"",QUARTILE(IF((Companies!$T$2:$T$301=$A3)*ISNUMBER(Companies!$I$2:$I$301),Companies!$I$2:$I$301),1)),"")} -> 3 | M3: {=IFERROR(IF($D3=0,"",MEDIAN(IF((Companies!$T$2:$T$301=$A3)*ISNUMBER(Companies!$I$2:$I$301),Companies!$I$2:$I$301))),"")} -> 4 | N3: {=IFERROR(IF($D3=0,"",QUARTILE(IF((Companies!$T$2:$T$301=$A3)*ISNUMBER(Companies!$I$2:$I$301),Companies!$I$2:$I$301),3)),"")} -> 6 | O3: {=IFERROR(IF($D3=0,"",MAX(IF((Companies!$T$2:$T$301=$A3)*ISNUMBER(Companies!$I$2:$I$301),Companies!$I$2:$I$301))),"")} -> 8 | P3: {=IF(MAX(Calc!$B5:$E5)=0,"",INDEX(Calc!$B$3:$E$3,MATCH(MAX(Calc!$B5:$E5),Calc!$B5:$E5,0)))} -> 100% top-up | Q3: {=IF(MAX(Calc!$G5:$J5)=0,"",INDEX(Calc!$G$3:$J$3,MATCH(MAX(Calc!$G5:$J5),Calc!$G5:$J5,0)))} -> 90 days | R3: {=IF(MAX(Calc!$L5:$N5)=0,"",INDEX(Calc!$L$3:$N$3,MATCH(MAX(Calc!$L5:$N5),Calc!$L5:$N5,0)))} -> Flexible chunks / 12 mo | S3: {=IF(MAX(Calc!$P5:$S5)=0,"",INDEX(Calc!$P$3:$S$3,MATCH(MAX(Calc!$P5:$S5),Calc!$P5:$S5,0)))} -> 1-2 wks
A4: Series A | Standard | B4: Series A | C4: Standard | D4: =COUNTIFS(Companies!$T$2:$T$301,$A4,Companies!$H$2:$H$301,">=0") -> 42 | E4: =IF($D4=0,"NO DATA",IF($D4<30,"LOW SAMPLE (n<30)","")) | F4: {=IFERROR(IF($D4=0,"",MIN(IF((Companies!$T$2:$T$301=$A4)*ISNUMBER(Companies!$H$2:$H$301),Companies!$H$2:$H$301))),"")} -> 8 | G4: {=IFERROR(IF($D4=0,"",QUARTILE(IF((Companies!$T$2:$T$301=$A4)*ISNUMBER(Companies!$H$2:$H$301),Companies!$H$2:$H$301),1)),"")} -> 10.25 | H4: {=IFERROR(IF($D4=0,"",MEDIAN(IF((Companies!$T$2:$T$301=$A4)*ISNUMBER(Companies!$H$2:$H$301),Companies!$H$2:$H$301))),"")} -> 12 | I4: {=IFERROR(IF($D4=0,"",QUARTILE(IF((Companies!$T$2:$T$301=$A4)*ISNUMBER(Companies!$H$2:$H$301),Companies!$H$2:$H$301),3)),"")} -> 14 | J4: {=IFERROR(IF($D4=0,"",MAX(IF((Companies!$T$2:$T$301=$A4)*ISNUMBER(Companies!$H$2:$H$301),Companies!$H$2:$H$301))),"")} -> 18 | K4: {=IFERROR(IF($D4=0,"",MIN(IF((Companies!$T$2:$T$301=$A4)*ISNUMBER(Companies!$I$2:$I$301),Companies!$I$2:$I$301))),"")} -> 4 | L4: {=IFERROR(IF($D4=0,"",QUARTILE(IF((Companies!$T$2:$T$301=$A4)*ISNUMBER(Companies!$I$2:$I$301),Companies!$I$2:$I$301),1)),"")} -> 5 | M4: {=IFERROR(IF($D4=0,"",MEDIAN(IF((Companies!$T$2:$T$301=$A4)*ISNUMBER(Companies!$I$2:$I$301),Companies!$I$2:$I$301))),"")} -> 7.5 | N4: {=IFERROR(IF($D4=0,"",QUARTILE(IF((Companies!$T$2:$T$301=$A4)*ISNUMBER(Companies!$I$2:$I$301),Companies!$I$2:$I$301),3)),"")} -> 9.75 | O4: {=IFERROR(IF($D4=0,"",MAX(IF((Companies!$T$2:$T$301=$A4)*ISNUMBER(Companies!$I$2:$I$301),Companies!$I$2:$I$301))),"")} -> 12 | P4: {=IF(MAX(Calc!$B6:$E6)=0,"",INDEX(Calc!$B$3:$E$3,MATCH(MAX(Calc!$B6:$E6),Calc!$B6:$E6,0)))} -> 100% top-up | Q4: {=IF(MAX(Calc!$G6:$J6)=0,"",INDEX(Calc!$G$3:$J$3,MATCH(MAX(Calc!$G6:$J6),Calc!$G6:$J6,0)))} -> Day 1 | R4: {=IF(MAX(Calc!$L6:$N6)=0,"",INDEX(Calc!$L$3:$N$3,MATCH(MAX(Calc!$L6:$N6),Calc!$L6:$N6,0)))} -> Flexible chunks / 12 mo | S4: {=IF(MAX(Calc!$P6:$S6)=0,"",INDEX(Calc!$P$3:$S$3,MATCH(MAX(Calc!$P6:$S6),Calc!$P6:$S6,0)))} -> <=1 wk
A5: Series A | High-cost | B5: Series A | C5: High-cost | D5: =COUNTIFS(Companies!$T$2:$T$301,$A5,Companies!$H$2:$H$301,">=0") -> 25 | E5: =IF($D5=0,"NO DATA",IF($D5<30,"LOW SAMPLE (n<30)","")) -> LOW SAMPLE (n<30) | F5: {=IFERROR(IF($D5=0,"",MIN(IF((Companies!$T$2:$T$301=$A5)*ISNUMBER(Companies!$H$2:$H$301),Companies!$H$2:$H$301))),"")} -> 8 | G5: {=IFERROR(IF($D5=0,"",QUARTILE(IF((Companies!$T$2:$T$301=$A5)*ISNUMBER(Companies!$H$2:$H$301),Companies!$H$2:$H$301),1)),"")} -> 12 | H5: {=IFERROR(IF($D5=0,"",MEDIAN(IF((Companies!$T$2:$T$301=$A5)*ISNUMBER(Companies!$H$2:$H$301),Companies!$H$2:$H$301))),"")} -> 14 | I5: {=IFERROR(IF($D5=0,"",QUARTILE(IF((Companies!$T$2:$T$301=$A5)*ISNUMBER(Companies!$H$2:$H$301),Companies!$H$2:$H$301),3)),"")} -> 16 | J5: {=IFERROR(IF($D5=0,"",MAX(IF((Companies!$T$2:$T$301=$A5)*ISNUMBER(Companies!$H$2:$H$301),Companies!$H$2:$H$301))),"")} -> 18 | K5: {=IFERROR(IF($D5=0,"",MIN(IF((Companies!$T$2:$T$301=$A5)*ISNUMBER(Companies!$I$2:$I$301),Companies!$I$2:$I$301))),"")} -> 4 | L5: {=IFERROR(IF($D5=0,"",QUARTILE(IF((Companies!$T$2:$T$301=$A5)*ISNUMBER(Companies!$I$2:$I$301),Companies!$I$2:$I$301),1)),"")} -> 6 | M5: {=IFERROR(IF($D5=0,"",MEDIAN(IF((Companies!$T$2:$T$301=$A5)*ISNUMBER(Companies!$I$2:$I$301),Companies!$I$2:$I$301))),"")} -> 7 | N5: {=IFERROR(IF($D5=0,"",QUARTILE(IF((Companies!$T$2:$T$301=$A5)*ISNUMBER(Companies!$I$2:$I$301),Companies!$I$2:$I$301),3)),"")} -> 9 | O5: {=IFERROR(IF($D5=0,"",MAX(IF((Companies!$T$2:$T$301=$A5)*ISNUMBER(Companies!$I$2:$I$301),Companies!$I$2:$I$301))),"")} -> 11 | P5: {=IF(MAX(Calc!$B7:$E7)=0,"",INDEX(Calc!$B$3:$E$3,MATCH(MAX(Calc!$B7:$E7),Calc!$B7:$E7,0)))} -> 100% top-up | Q5: {=IF(MAX(Calc!$G7:$J7)=0,"",INDEX(Calc!$G$3:$J$3,MATCH(MAX(Calc!$G7:$J7),Calc!$G7:$J7,0)))} -> 6 months | R5: {=IF(MAX(Calc!$L7:$N7)=0,"",INDEX(Calc!$L$3:$N$3,MATCH(MAX(Calc!$L7:$N7),Calc!$L7:$N7,0)))} -> Single block | S5: {=IF(MAX(Calc!$P7:$S7)=0,"",INDEX(Calc!$P$3:$S$3,MATCH(MAX(Calc!$P7:$S7),Calc!$P7:$S7,0)))} -> None
A6: Series B+ | Standard | B6: Series B+ | C6: Standard | D6: =COUNTIFS(Companies!$T$2:$T$301,$A6,Companies!$H$2:$H$301,">=0") -> 46 | E6: =IF($D6=0,"NO DATA",IF($D6<30,"LOW SAMPLE (n<30)","")) | F6: {=IFERROR(IF($D6=0,"",MIN(IF((Companies!$T$2:$T$301=$A6)*ISNUMBER(Companies!$H$2:$H$301),Companies!$H$2:$H$301))),"")} -> 11 | G6: {=IFERROR(IF($D6=0,"",QUARTILE(IF((Companies!$T$2:$T$301=$A6)*ISNUMBER(Companies!$H$2:$H$301),Companies!$H$2:$H$301),1)),"")} -> 14 | H6: {=IFERROR(IF($D6=0,"",MEDIAN(IF((Companies!$T$2:$T$301=$A6)*ISNUMBER(Companies!$H$2:$H$301),Companies!$H$2:$H$301))),"")} -> 18 | I6: {=IFERROR(IF($D6=0,"",QUARTILE(IF((Companies!$T$2:$T$301=$A6)*ISNUMBER(Companies!$H$2:$H$301),Companies!$H$2:$H$301),3)),"")} -> 20 | J6: {=IFERROR(IF($D6=0,"",MAX(IF((Companies!$T$2:$T$301=$A6)*ISNUMBER(Companies!$H$2:$H$301),Companies!$H$2:$H$301))),"")} -> 24 | K6: {=IFERROR(IF($D6=0,"",MIN(IF((Companies!$T$2:$T$301=$A6)*ISNUMBER(Companies!$I$2:$I$301),Companies!$I$2:$I$301))),"")} -> 4 | L6: {=IFERROR(IF($D6=0,"",QUARTILE(IF((Companies!$T$2:$T$301=$A6)*ISNUMBER(Companies!$I$2:$I$301),Companies!$I$2:$I$301),1)),"")} -> 6 | M6: {=IFERROR(IF($D6=0,"",MEDIAN(IF((Companies!$T$2:$T$301=$A6)*ISNUMBER(Companies!$I$2:$I$301),Companies!$I$2:$I$301))),"")} -> 10 | N6: {=IFERROR(IF($D6=0,"",QUARTILE(IF((Companies!$T$2:$T$301=$A6)*ISNUMBER(Companies!$I$2:$I$301),Companies!$I$2:$I$301),3)),"")} -> 13 | O6: {=IFERROR(IF($D6=0,"",MAX(IF((Companies!$T$2:$T$301=$A6)*ISNUMBER(Companies!$I$2:$I$301),Companies!$I$2:$I$301))),"")} -> 16 | P6: {=IF(MAX(Calc!$B8:$E8)=0,"",INDEX(Calc!$B$3:$E$3,MATCH(MAX(Calc!$B8:$E8),Calc!$B8:$E8,0)))} -> 100% top-up | Q6: {=IF(MAX(Calc!$G8:$J8)=0,"",INDEX(Calc!$G$3:$J$3,MATCH(MAX(Calc!$G8:$J8),Calc!$G8:$J8,0)))} -> 90 days | R6: {=IF(MAX(Calc!$L8:$N8)=0,"",INDEX(Calc!$L$3:$N$3,MATCH(MAX(Calc!$L8:$N8),Calc!$L8:$N8,0)))} -> Flexible chunks / 12 mo | S6: {=IF(MAX(Calc!$P8:$S8)=0,"",INDEX(Calc!$P$3:$S$3,MATCH(MAX(Calc!$P8:$S8),Calc!$P8:$S8,0)))} -> None
A7: Series B+ | High-cost | B7: Series B+ | C7: High-cost | D7: =COUNTIFS(Companies!$T$2:$T$301,$A7,Companies!$H$2:$H$301,">=0") -> 21 | E7: =IF($D7=0,"NO DATA",IF($D7<30,"LOW SAMPLE (n<30)","")) -> LOW SAMPLE (n<30) | F7: {=IFERROR(IF($D7=0,"",MIN(IF((Companies!$T$2:$T$301=$A7)*ISNUMBER(Companies!$H$2:$H$301),Companies!$H$2:$H$301))),"")} -> 10 | G7: {=IFERROR(IF($D7=0,"",QUARTILE(IF((Companies!$T$2:$T$301=$A7)*ISNUMBER(Companies!$H$2:$H$301),Companies!$H$2:$H$301),1)),"")} -> 12 | H7: {=IFERROR(IF($D7=0,"",MEDIAN(IF((Companies!$T$2:$T$301=$A7)*ISNUMBER(Companies!$H$2:$H$301),Companies!$H$2:$H$301))),"")} -> 16 | I7: {=IFERROR(IF($D7=0,"",QUARTILE(IF((Companies!$T$2:$T$301=$A7)*ISNUMBER(Companies!$H$2:$H$301),Companies!$H$2:$H$301),3)),"")} -> 21 | J7: {=IFERROR(IF($D7=0,"",MAX(IF((Companies!$T$2:$T$301=$A7)*ISNUMBER(Companies!$H$2:$H$301),Companies!$H$2:$H$301))),"")} -> 24 | K7: {=IFERROR(IF($D7=0,"",MIN(IF((Companies!$T$2:$T$301=$A7)*ISNUMBER(Companies!$I$2:$I$301),Companies!$I$2:$I$301))),"")} -> 4 | L7: {=IFERROR(IF($D7=0,"",QUARTILE(IF((Companies!$T$2:$T$301=$A7)*ISNUMBER(Companies!$I$2:$I$301),Companies!$I$2:$I$301),1)),"")} -> 6 | M7: {=IFERROR(IF($D7=0,"",MEDIAN(IF((Companies!$T$2:$T$301=$A7)*ISNUMBER(Companies!$I$2:$I$301),Companies!$I$2:$I$301))),"")} -> 9 | N7: {=IFERROR(IF($D7=0,"",QUARTILE(IF((Companies!$T$2:$T$301=$A7)*ISNUMBER(Companies!$I$2:$I$301),Companies!$I$2:$I$301),3)),"")} -> 12 | O7: {=IFERROR(IF($D7=0,"",MAX(IF((Companies!$T$2:$T$301=$A7)*ISNUMBER(Companies!$I$2:$I$301),Companies!$I$2:$I$301))),"")} -> 15 | P7: {=IF(MAX(Calc!$B9:$E9)=0,"",INDEX(Calc!$B$3:$E$3,MATCH(MAX(Calc!$B9:$E9),Calc!$B9:$E9,0)))} -> 100% top-up | Q7: {=IF(MAX(Calc!$G9:$J9)=0,"",INDEX(Calc!$G$3:$J$3,MATCH(MAX(Calc!$G9:$J9),Calc!$G9:$J9,0)))} -> 12 months | R7: {=IF(MAX(Calc!$L9:$N9)=0,"",INDEX(Calc!$L$3:$N$3,MATCH(MAX(Calc!$L9:$N9),Calc!$L9:$N9,0)))} -> Single block | S7: {=IF(MAX(Calc!$P9:$S9)=0,"",INDEX(Calc!$P$3:$S$3,MATCH(MAX(Calc!$P9:$S9),Calc!$P9:$S9,0)))} -> None

Sheet BackendInternal-->

Sheet Calc
B1: Machinery for the 'typical' columns on Benchmarks — counts per segment per option. Don't edit.
A2: Segment | B2: Pay | G2: Elig | L2: Flex | P2: Ramp
B3: ='Ranges - Config'!$D$2 -> 100% top-up | C3: ='Ranges - Config'!$D$3 -> Partial top-up | D3: ='Ranges - Config'!$D$4 -> STD only | E3: ='Ranges - Config'!$D$5 -> Unpaid beyond legal | G3: ='Ranges - Config'!$E$2 -> Day 1 | H3: ='Ranges - Config'!$E$3 -> 90 days | I3: ='Ranges - Config'!$E$4 -> 6 months | J3: ='Ranges - Config'!$E$5 -> 12 months | L3: ='Ranges - Config'!$F$2 -> Single block | M3: ='Ranges - Config'!$F$3 -> 2 chunks | N3: ='Ranges - Config'!$F$4 -> Flexible chunks / 12 mo | P3: ='Ranges - Config'!$G$2 -> None | Q3: ='Ranges - Config'!$G$3 -> <=1 wk | R3: ='Ranges - Config'!$G$4 -> 1-2 wks | S3: ='Ranges - Config'!$G$5 -> 2-4 wks
A4: Seed | Standard | B4: =COUNTIFS(Companies!$T$2:$T$301,Benchmarks!$A2,Companies!$J$2:$J$301,B$3) -> 29 | C4: =COUNTIFS(Companies!$T$2:$T$301,Benchmarks!$A2,Companies!$J$2:$J$301,C$3) -> 10 | D4: =COUNTIFS(Companies!$T$2:$T$301,Benchmarks!$A2,Companies!$J$2:$J$301,D$3) -> 12 | E4: =COUNTIFS(Companies!$T$2:$T$301,Benchmarks!$A2,Companies!$J$2:$J$301,E$3) -> 1 | G4: =COUNTIFS(Companies!$T$2:$T$301,Benchmarks!$A2,Companies!$L$2:$L$301,G$3) -> 10 | H4: =COUNTIFS(Companies!$T$2:$T$301,Benchmarks!$A2,Companies!$L$2:$L$301,H$3) -> 10 | I4: =COUNTIFS(Companies!$T$2:$T$301,Benchmarks!$A2,Companies!$L$2:$L$301,I$3) -> 10 | J4: =COUNTIFS(Companies!$T$2:$T$301,Benchmarks!$A2,Companies!$L$2:$L$301,J$3) -> 20 | L4: =COUNTIFS(Companies!$T$2:$T$301,Benchmarks!$A2,Companies!$M$2:$M$301,L$3) -> 18 | M4: =COUNTIFS(Companies!$T$2:$T$301,Benchmarks!$A2,Companies!$M$2:$M$301,M$3) -> 14 | N4: =COUNTIFS(Companies!$T$2:$T$301,Benchmarks!$A2,Companies!$M$2:$M$301,N$3) -> 18 | P4: =COUNTIFS(Companies!$T$2:$T$301,Benchmarks!$A2,Companies!$N$2:$N$301,P$3) -> 19 | Q4: =COUNTIFS(Companies!$T$2:$T$301,Benchmarks!$A2,Companies!$N$2:$N$301,Q$3) -> 11 | R4: =COUNTIFS(Companies!$T$2:$T$301,Benchmarks!$A2,Companies!$N$2:$N$301,R$3) -> 15 | S4: =COUNTIFS(Companies!$T$2:$T$301,Benchmarks!$A2,Companies!$N$2:$N$301,S$3) -> 6
A5: Seed | High-cost | B5: =COUNTIFS(Companies!$T$2:$T$301,Benchmarks!$A3,Companies!$J$2:$J$301,B$3) -> 9 | C5: =COUNTIFS(Companies!$T$2:$T$301,Benchmarks!$A3,Companies!$J$2:$J$301,C$3) -> 6 | D5: =COUNTIFS(Companies!$T$2:$T$301,Benchmarks!$A3,Companies!$J$2:$J$301,D$3) -> 4 | E5: =COUNTIFS(Companies!$T$2:$T$301,Benchmarks!$A3,Companies!$J$2:$J$301,E$3) -> 2 | G5: =COUNTIFS(Companies!$T$2:$T$301,Benchmarks!$A3,Companies!$L$2:$L$301,G$3) -> 4 | H5: =COUNTIFS(Companies!$T$2:$T$301,Benchmarks!$A3,Companies!$L$2:$L$301,H$3) -> 6 | I5: =COUNTIFS(Companies!$T$2:$T$301,Benchmarks!$A3,Companies!$L$2:$L$301,I$3) -> 6 | J5: =COUNTIFS(Companies!$T$2:$T$301,Benchmarks!$A3,Companies!$L$2:$L$301,J$3) -> 5 | L5: =COUNTIFS(Companies!$T$2:$T$301,Benchmarks!$A3,Companies!$M$2:$M$301,L$3) -> 5 | M5: =COUNTIFS(Companies!$T$2:$T$301,Benchmarks!$A3,Companies!$M$2:$M$301,M$3) -> 4 | N5: =COUNTIFS(Companies!$T$2:$T$301,Benchmarks!$A3,Companies!$M$2:$M$301,N$3) -> 12 | P5: =COUNTIFS(Companies!$T$2:$T$301,Benchmarks!$A3,Companies!$N$2:$N$301,P$3) -> 7 | Q5: =COUNTIFS(Companies!$T$2:$T$301,Benchmarks!$A3,Companies!$N$2:$N$301,Q$3) -> 5 | R5: =COUNTIFS(Companies!$T$2:$T$301,Benchmarks!$A3,Companies!$N$2:$N$301,R$3) -> 8 | S5: =COUNTIFS(Companies!$T$2:$T$301,Benchmarks!$A3,Companies!$N$2:$N$301,S$3) -> 1
A6: Series A | Standard | B6: =COUNTIFS(Companies!$T$2:$T$301,Benchmarks!$A4,Companies!$J$2:$J$301,B$3) -> 24 | C6: =COUNTIFS(Companies!$T$2:$T$301,Benchmarks!$A4,Companies!$J$2:$J$301,C$3) -> 11 | D6: =COUNTIFS(Companies!$T$2:$T$301,Benchmarks!$A4,Companies!$J$2:$J$301,D$3) -> 4 | E6: =COUNTIFS(Companies!$T$2:$T$301,Benchmarks!$A4,Companies!$J$2:$J$301,E$3) -> 3 | G6: =COUNTIFS(Companies!$T$2:$T$301,Benchmarks!$A4,Companies!$L$2:$L$301,G$3) -> 15 | H6: =COUNTIFS(Companies!$T$2:$T$301,Benchmarks!$A4,Companies!$L$2:$L$301,H$3) -> 6 | I6: =COUNTIFS(Companies!$T$2:$T$301,Benchmarks!$A4,Companies!$L$2:$L$301,I$3) -> 10 | J6: =COUNTIFS(Companies!$T$2:$T$301,Benchmarks!$A4,Companies!$L$2:$L$301,J$3) -> 11 | L6: =COUNTIFS(Companies!$T$2:$T$301,Benchmarks!$A4,Companies!$M$2:$M$301,L$3) -> 12 | M6: =COUNTIFS(Companies!$T$2:$T$301,Benchmarks!$A4,Companies!$M$2:$M$301,M$3) -> 13 | N6: =COUNTIFS(Companies!$T$2:$T$301,Benchmarks!$A4,Companies!$M$2:$M$301,N$3) -> 17 | P6: =COUNTIFS(Companies!$T$2:$T$301,Benchmarks!$A4,Companies!$N$2:$N$301,P$3) -> 10 | Q6: =COUNTIFS(Companies!$T$2:$T$301,Benchmarks!$A4,Companies!$N$2:$N$301,Q$3) -> 16 | R6: =COUNTIFS(Companies!$T$2:$T$301,Benchmarks!$A4,Companies!$N$2:$N$301,R$3) -> 10 | S6: =COUNTIFS(Companies!$T$2:$T$301,Benchmarks!$A4,Companies!$N$2:$N$301,S$3) -> 6
A7: Series A | High-cost | B7: =COUNTIFS(Companies!$T$2:$T$301,Benchmarks!$A5,Companies!$J$2:$J$301,B$3) -> 14 | C7: =COUNTIFS(Companies!$T$2:$T$301,Benchmarks!$A5,Companies!$J$2:$J$301,C$3) -> 8 | D7: =COUNTIFS(Companies!$T$2:$T$301,Benchmarks!$A5,Companies!$J$2:$J$301,D$3) -> 3 | E7: =COUNTIFS(Companies!$T$2:$T$301,Benchmarks!$A5,Companies!$J$2:$J$301,E$3) -> 0 | G7: =COUNTIFS(Companies!$T$2:$T$301,Benchmarks!$A5,Companies!$L$2:$L$301,G$3) -> 6 | H7: =COUNTIFS(Companies!$T$2:$T$301,Benchmarks!$A5,Companies!$L$2:$L$301,H$3) -> 5 | I7: =COUNTIFS(Companies!$T$2:$T$301,Benchmarks!$A5,Companies!$L$2:$L$301,I$3) -> 8 | J7: =COUNTIFS(Companies!$T$2:$T$301,Benchmarks!$A5,Companies!$L$2:$L$301,J$3) -> 6 | L7: =COUNTIFS(Companies!$T$2:$T$301,Benchmarks!$A5,Companies!$M$2:$M$301,L$3) -> 9 | M7: =COUNTIFS(Companies!$T$2:$T$301,Benchmarks!$A5,Companies!$M$2:$M$301,M$3) -> 7 | N7: =COUNTIFS(Companies!$T$2:$T$301,Benchmarks!$A5,Companies!$M$2:$M$301,N$3) -> 9 | P7: =COUNTIFS(Companies!$T$2:$T$301,Benchmarks!$A5,Companies!$N$2:$N$301,P$3) -> 12 | Q7: =COUNTIFS(Companies!$T$2:$T$301,Benchmarks!$A5,Companies!$N$2:$N$301,Q$3) -> 5 | R7: =COUNTIFS(Companies!$T$2:$T$301,Benchmarks!$A5,Companies!$N$2:$N$301,R$3) -> 5 | S7: =COUNTIFS(Companies!$T$2:$T$301,Benchmarks!$A5,Companies!$N$2:$N$301,S$3) -> 3
A8: Series B+ | Standard | B8: =COUNTIFS(Companies!$T$2:$T$301,Benchmarks!$A6,Companies!$J$2:$J$301,B$3) -> 27 | C8: =COUNTIFS(Companies!$T$2:$T$301,Benchmarks!$A6,Companies!$J$2:$J$301,C$3) -> 12 | D8: =COUNTIFS(Companies!$T$2:$T$301,Benchmarks!$A6,Companies!$J$2:$J$301,D$3) -> 7 | E8: =COUNTIFS(Companies!$T$2:$T$301,Benchmarks!$A6,Companies!$J$2:$J$301,E$3) -> 0 | G8: =COUNTIFS(Companies!$T$2:$T$301,Benchmarks!$A6,Companies!$L$2:$L$301,G$3) -> 7 | H8: =COUNTIFS(Companies!$T$2:$T$301,Benchmarks!$A6,Companies!$L$2:$L$301,H$3) -> 13 | I8: =COUNTIFS(Companies!$T$2:$T$301,Benchmarks!$A6,Companies!$L$2:$L$301,I$3) -> 12 | J8: =COUNTIFS(Companies!$T$2:$T$301,Benchmarks!$A6,Companies!$L$2:$L$301,J$3) -> 12 | L8: =COUNTIFS(Companies!$T$2:$T$301,Benchmarks!$A6,Companies!$M$2:$M$301,L$3) -> 14 | M8: =COUNTIFS(Companies!$T$2:$T$301,Benchmarks!$A6,Companies!$M$2:$M$301,M$3) -> 14 | N8: =COUNTIFS(Companies!$T$2:$T$301,Benchmarks!$A6,Companies!$M$2:$M$301,N$3) -> 17 | P8: =COUNTIFS(Companies!$T$2:$T$301,Benchmarks!$A6,Companies!$N$2:$N$301,P$3) -> 19 | Q8: =COUNTIFS(Companies!$T$2:$T$301,Benchmarks!$A6,Companies!$N$2:$N$301,Q$3) -> 11 | R8: =COUNTIFS(Companies!$T$2:$T$301,Benchmarks!$A6,Companies!$N$2:$N$301,R$3) -> 9 | S8: =COUNTIFS(Companies!$T$2:$T$301,Benchmarks!$A6,Companies!$N$2:$N$301,S$3) -> 5
A9: Series B+ | High-cost | B9: =COUNTIFS(Companies!$T$2:$T$301,Benchmarks!$A7,Companies!$J$2:$J$301,B$3) -> 12 | C9: =COUNTIFS(Companies!$T$2:$T$301,Benchmarks!$A7,Companies!$J$2:$J$301,C$3) -> 3 | D9: =COUNTIFS(Companies!$T$2:$T$301,Benchmarks!$A7,Companies!$J$2:$J$301,D$3) -> 4 | E9: =COUNTIFS(Companies!$T$2:$T$301,Benchmarks!$A7,Companies!$J$2:$J$301,E$3) -> 2 | G9: =COUNTIFS(Companies!$T$2:$T$301,Benchmarks!$A7,Companies!$L$2:$L$301,G$3) -> 4 | H9: =COUNTIFS(Companies!$T$2:$T$301,Benchmarks!$A7,Companies!$L$2:$L$301,H$3) -> 3 | I9: =COUNTIFS(Companies!$T$2:$T$301,Benchmarks!$A7,Companies!$L$2:$L$301,I$3) -> 3 | J9: =COUNTIFS(Companies!$T$2:$T$301,Benchmarks!$A7,Companies!$L$2:$L$301,J$3) -> 9 | L9: =COUNTIFS(Companies!$T$2:$T$301,Benchmarks!$A7,Companies!$M$2:$M$301,L$3) -> 8 | M9: =COUNTIFS(Companies!$T$2:$T$301,Benchmarks!$A7,Companies!$M$2:$M$301,M$3) -> 4 | N9: =COUNTIFS(Companies!$T$2:$T$301,Benchmarks!$A7,Companies!$M$2:$M$301,N$3) -> 7 | P9: =COUNTIFS(Companies!$T$2:$T$301,Benchmarks!$A7,Companies!$N$2:$N$301,P$3) -> 9 | Q9: =COUNTIFS(Companies!$T$2:$T$301,Benchmarks!$A7,Companies!$N$2:$N$301,Q$3) -> 3 | R9: =COUNTIFS(Companies!$T$2:$T$301,Benchmarks!$A7,Companies!$N$2:$N$301,R$3) -> 3 | S9: =COUNTIFS(Companies!$T$2:$T$301,Benchmarks!$A7,Companies!$N$2:$N$301,S$3) -> 4

Sheet Tool Export
A1: Segment | B1: Birthing Weeks — Floor (min) | C1: Birthing Weeks — Typical (mid) | D1: Birthing Weeks — Range Label | E1: Non-Birthing Weeks — Floor (min) | F1: Non-Birthing Weeks — Typical (mid) | G1: Non-Birthing Weeks — Range Label | H1: Pay Structure (payFT) | I1: Eligibility Rule (eligibility) | J1: Flexibility Option (flexibility) | K1: Ramp-Up Program (rampUp) | L1: Data Confidence Warning
A2: =Benchmarks!$A2 -> Seed | Standard | B2: =Benchmarks!$G2 -> 9 | C2: =Benchmarks!$H2 -> 11 | D2: =IF(OR(Benchmarks!$G2="",Benchmarks!$I2=""),"",TEXT(Benchmarks!$G2,"0")&"-"&TEXT(Benchmarks!$I2,"0")&" wks") -> 9-12 wks | E2: =Benchmarks!$L2 -> 3 | F2: =Benchmarks!$M2 -> 5 | G2: =IF(OR(Benchmarks!$L2="",Benchmarks!$N2=""),"",TEXT(Benchmarks!$L2,"0")&"-"&TEXT(Benchmarks!$N2,"0")&" wks") -> 3-7 wks | H2: =Benchmarks!$P2 -> 100% top-up | I2: =Benchmarks!$Q2 -> 12 months | J2: =Benchmarks!$R2 -> Single block | K2: =Benchmarks!$S2 -> None | L2: =Benchmarks!$E2
A3: =Benchmarks!$A3 -> Seed | High-cost | B3: =Benchmarks!$G3 -> 8 | C3: =Benchmarks!$H3 -> 10 | D3: =IF(OR(Benchmarks!$G3="",Benchmarks!$I3=""),"",TEXT(Benchmarks!$G3,"0")&"-"&TEXT(Benchmarks!$I3,"0")&" wks") -> 8-13 wks | E3: =Benchmarks!$L3 -> 3 | F3: =Benchmarks!$M3 -> 4 | G3: =IF(OR(Benchmarks!$L3="",Benchmarks!$N3=""),"",TEXT(Benchmarks!$L3,"0")&"-"&TEXT(Benchmarks!$N3,"0")&" wks") -> 3-6 wks | H3: =Benchmarks!$P3 -> 100% top-up | I3: =Benchmarks!$Q3 -> 90 days | J3: =Benchmarks!$R3 -> Flexible chunks / 12 mo | K3: =Benchmarks!$S3 -> 1-2 wks | L3: =Benchmarks!$E3 -> LOW SAMPLE (n<30)
A4: =Benchmarks!$A4 -> Series A | Standard | B4: =Benchmarks!$G4 -> 10.25 | C4: =Benchmarks!$H4 -> 12 | D4: =IF(OR(Benchmarks!$G4="",Benchmarks!$I4=""),"",TEXT(Benchmarks!$G4,"0")&"-"&TEXT(Benchmarks!$I4,"0")&" wks") -> 10-14 wks | E4: =Benchmarks!$L4 -> 5 | F4: =Benchmarks!$M4 -> 7.5 | G4: =IF(OR(Benchmarks!$L4="",Benchmarks!$N4=""),"",TEXT(Benchmarks!$L4,"0")&"-"&TEXT(Benchmarks!$N4,"0")&" wks") -> 5-10 wks | H4: =Benchmarks!$P4 -> 100% top-up | I4: =Benchmarks!$Q4 -> Day 1 | J4: =Benchmarks!$R4 -> Flexible chunks / 12 mo | K4: =Benchmarks!$S4 -> <=1 wk | L4: =Benchmarks!$E4
A5: =Benchmarks!$A5 -> Series A | High-cost | B5: =Benchmarks!$G5 -> 12 | C5: =Benchmarks!$H5 -> 14 | D5: =IF(OR(Benchmarks!$G5="",Benchmarks!$I5=""),"",TEXT(Benchmarks!$G5,"0")&"-"&TEXT(Benchmarks!$I5,"0")&" wks") -> 12-16 wks | E5: =Benchmarks!$L5 -> 6 | F5: =Benchmarks!$M5 -> 7 | G5: =IF(OR(Benchmarks!$L5="",Benchmarks!$N5=""),"",TEXT(Benchmarks!$L5,"0")&"-"&TEXT(Benchmarks!$N5,"0")&" wks") -> 6-9 wks | H5: =Benchmarks!$P5 -> 100% top-up | I5: =Benchmarks!$Q5 -> 6 months | J5: =Benchmarks!$R5 -> Single block | K5: =Benchmarks!$S5 -> None | L5: =Benchmarks!$E5 -> LOW SAMPLE (n<30)
A6: =Benchmarks!$A6 -> Series B+ | Standard | B6: =Benchmarks!$G6 -> 14 | C6: =Benchmarks!$H6 -> 18 | D6: =IF(OR(Benchmarks!$G6="",Benchmarks!$I6=""),"",TEXT(Benchmarks!$G6,"0")&"-"&TEXT(Benchmarks!$I6,"0")&" wks") -> 14-20 wks | E6: =Benchmarks!$L6 -> 6 | F6: =Benchmarks!$M6 -> 10 | G6: =IF(OR(Benchmarks!$L6="",Benchmarks!$N6=""),"",TEXT(Benchmarks!$L6,"0")&"-"&TEXT(Benchmarks!$N6,"0")&" wks") -> 6-13 wks | H6: =Benchmarks!$P6 -> 100% top-up | I6: =Benchmarks!$Q6 -> 90 days | J6: =Benchmarks!$R6 -> Flexible chunks / 12 mo | K6: =Benchmarks!$S6 -> None | L6: =Benchmarks!$E6
A7: =Benchmarks!$A7 -> Series B+ | High-cost | B7: =Benchmarks!$G7 -> 12 | C7: =Benchmarks!$H7 -> 16 | D7: =IF(OR(Benchmarks!$G7="",Benchmarks!$I7=""),"",TEXT(Benchmarks!$G7,"0")&"-"&TEXT(Benchmarks!$I7,"0")&" wks") -> 12-21 wks | E7: =Benchmarks!$L7 -> 6 | F7: =Benchmarks!$M7 -> 9 | G7: =IF(OR(Benchmarks!$L7="",Benchmarks!$N7=""),"",TEXT(Benchmarks!$L7,"0")&"-"&TEXT(Benchmarks!$N7,"0")&" wks") -> 6-12 wks | H7: =Benchmarks!$P7 -> 100% top-up | I7: =Benchmarks!$Q7 -> 12 months | J7: =Benchmarks!$R7 -> Single block | K7: =Benchmarks!$S7 -> None | L7: =Benchmarks!$E7 -> LOW SAMPLE (n<30)
